#VRML_SIM R2025a utf8
# license: Apache License 2.0
# license url: http://www.apache.org/licenses/LICENSE-2.0
# This is a proto file for Webots for the robot
# Extracted from: /Users/haiyunning/Desktop/0 Py project/Robotics/robot.urdf

PROTO robot[
  field  SFVec3f     translation     0 0 0
  field  SFRotation  rotation        0 0 1 0
  field  SFString    name            "robot"  # Is `Robot.name`.
  field  SFString    controller      ""   # Is `Robot.controller`.
  field  MFString    controllerArgs  []       # Is `Robot.controllerArgs`.
  field  SFString    customData      ""       # Is `Robot.customData`.
  field  SFBool      supervisor      FALSE    # Is `Robot.supervisor`.
  field  SFBool      synchronization TRUE     # Is `Robot.synchronization`.
  field  SFBool      selfCollision   FALSE    # Is `Robot.selfCollision`.
]
{
  Robot {
    translation IS translation
    rotation IS rotation
    controller IS controller
    controllerArgs IS controllerArgs
    customData IS customData
    supervisor IS supervisor
    synchronization IS synchronization
    selfCollision IS selfCollision
    children [
      Pose {
        translation 0.000000 0.000000 0.500000  # Place above the base box
        children [
          # Visible representation of the IMU
          Shape {
            appearance PBRAppearance {
              baseColor 1.000 0.000 0.000  # Red to make it stand out
              roughness 1.000
              metalness 0
            }
            geometry Box {
              size 0.05 0.05 0.05  # Small box to represent the IMU
            }
          }
          
          # The actual IMU sensor
          InertialUnit {
            name "imu_sensor"
          }
          Emitter {
            name "robot_emitter"
            channel 1
          }
        ]
      }
      Pose {
        translation 0.000000 0.000000 0.400000
        children [
          Shape {
            appearance DEF blue PBRAppearance {
              baseColor 0.000000 0.000000 1.000000
              roughness 1.000000
              metalness 0
            }
            geometry Box {
               size 0.300000 0.200000 0.100000
            }
          }
        ]
      }
      HingeJoint {
        jointParameters HingeJointParameters {
          axis 1.000000 0.000000 0.000000
          anchor 0 0 0.000000
        }
        device [
          RotationalMotor {
            name "left_wheel_joint"
            maxTorque 10000
          }
          PositionSensor {
            name "left_wheel_joint_sensor"
          }
        ]
        endPoint Solid {
          translation -0.150000 -0.100000 0.000000
          children [
            Pose {
              translation 0.000000 0.100000 0.000000
              rotation 0.000000 1.000000 0.000000 1.570800
              children [
                Shape {
                  appearance DEF gray PBRAppearance {
                    baseColor 0.500000 0.500000 0.500000
                    roughness 1.000000
                    metalness 0
                  }
                  geometry Cylinder {
                    radius 0.05
                    height 0.02
                  }
                }
              ]
            }
          ]
          name "left_wheel"
          boundingObject Pose {
            translation 0.000000 0.100000 0.000000
            rotation 0.000000 1.000000 0.000000 1.570800
            children [
              Cylinder {
                radius 0.05
                height 0.02
              }
            ]
          }
          physics Physics {
            density -1
            mass 0.500000
            centerOfMass [ 0.000000 0.100000 0.000000 ]
            inertiaMatrix [
              1.000000e-02 1.000000e-02 1.000000e-02
              0.000000e+00 0.000000e+00 0.000000e+00
            ]
          }
        }
      }
      HingeJoint {
        jointParameters HingeJointParameters {
          axis 1.000000 0.000000 0.000000
          anchor 0 0 0.000000
        }
        device [
          RotationalMotor {
            name "right_wheel_joint"
            maxTorque 10000
          }
          PositionSensor {
            name "right_wheel_joint_sensor"
          }
        ]
        endPoint Solid {
          translation 0.150000 -0.100000 0.000000
          children [
            Pose {
              translation 0.000000 0.100000 0.000000
              rotation 0.000000 1.000000 0.000000 1.570800
              children [
                Shape {
                  appearance USE gray
                  geometry Cylinder {
                    radius 0.05
                    height 0.02
                  }
                }
              ]
            }
          ]
          name "right_wheel"
          boundingObject Pose {
            translation 0.000000 0.100000 0.000000
            rotation 0.000000 1.000000 0.000000 1.570800
            children [
              Cylinder {
                radius 0.05
                height 0.02
              }
            ]
          }
          physics Physics {
            density -1
            mass 0.500000
            centerOfMass [ 0.000000 0.100000 0.000000 ]
            inertiaMatrix [
              1.000000e-02 1.000000e-02 1.000000e-02
              0.000000e+00 0.000000e+00 0.000000e+00
            ]
          }
        }
      }
      HingeJoint {
        jointParameters HingeJointParameters {
          anchor -0.150000 0.000000 0.000000
        }
        device [
          RotationalMotor {
            name "left_hip_joint"
            maxVelocity 1.0
            minPosition -1.57
            maxPosition 1.57
            maxTorque 10.0
          }
          PositionSensor {
            name "left_hip_joint_sensor"
          }
        ]
        endPoint Solid {
          translation -0.150000 0.000000 0.000000
          children [
            Pose {
              translation 0.000000 0.000000 0.100000
              children [
                Shape {
                  appearance DEF red PBRAppearance {
                    baseColor 1.000000 0.000000 0.000000
                    roughness 1.000000
                    metalness 0
                  }
                  geometry Box {
                     size 0.100000 0.050000 0.200000
                  }
                }
              ]
            }
            HingeJoint {
              jointParameters HingeJointParameters {
                anchor 0.000000 0.000000 0.200000
              }
              device [
                RotationalMotor {
                  name "left_knee_joint"
                  maxVelocity 1.0
                  maxPosition 1.57
                  maxTorque 10.0
                }
                PositionSensor {
                  name "left_knee_joint_sensor"
                }
              ]
              endPoint Solid {
                translation 0.000000 0.000000 0.200000
                children [
                  Pose {
                    translation 0.000000 0.000000 0.100000
                    children [
                      Shape {
                        appearance DEF green PBRAppearance {
                          baseColor 0.000000 1.000000 0.000000
                          roughness 1.000000
                          metalness 0
                        }
                        geometry Box {
                           size 0.100000 0.050000 0.200000
                        }
                      }
                    ]
                  }
                ]
                name "left_lower_leg"
                boundingObject Pose {
                  translation 0.000000 0.000000 0.100000
                  children [
                    Box {
                       size 0.100000 0.050000 0.200000
                    }
                  ]
                }
                physics Physics {
                  density -1
                  mass 0.500000
                  centerOfMass [ 0.000000 0.000000 0.100000 ]
                  inertiaMatrix [
                    1.000000e-02 1.000000e-02 1.000000e-02
                    0.000000e+00 0.000000e+00 0.000000e+00
                  ]
                }
              }
            }
          ]
          name "left_upper_leg"
          boundingObject Pose {
            translation 0.000000 0.000000 0.100000
            children [
              Box {
                 size 0.100000 0.050000 0.200000
              }
            ]
          }
          physics Physics {
            density -1
            mass 1.000000
            centerOfMass [ 0.000000 0.000000 0.100000 ]
            inertiaMatrix [
              1.000000e-02 1.000000e-02 1.000000e-02
              0.000000e+00 0.000000e+00 0.000000e+00
            ]
          }
        }
      }
      HingeJoint {
        jointParameters HingeJointParameters {
          anchor 0.150000 0.000000 0.000000
        }
        device [
          RotationalMotor {
            name "right_hip_joint"
            maxVelocity 1.0
            minPosition -1.57
            maxPosition 1.57
            maxTorque 10.0
          }
          PositionSensor {
            name "right_hip_joint_sensor"
          }
        ]
        endPoint Solid {
          translation 0.150000 0.000000 0.000000
          children [
            Pose {
              translation 0.000000 0.000000 0.100000
              children [
                Shape {
                  appearance USE red
                  geometry Box {
                     size 0.100000 0.050000 0.200000
                  }
                }
              ]
            }
            HingeJoint {
              jointParameters HingeJointParameters {
                anchor 0.000000 0.000000 0.200000
              }
              device [
                RotationalMotor {
                  name "right_knee_joint"
                  maxVelocity 1.0
                  maxPosition 1.57
                  maxTorque 10.0
                }
                PositionSensor {
                  name "right_knee_joint_sensor"
                }
              ]
              endPoint Solid {
                translation 0.000000 0.000000 0.200000
                children [
                  Pose {
                    translation 0.000000 0.000000 0.100000
                    children [
                      Shape {
                        appearance USE green
                        geometry Box {
                           size 0.100000 0.050000 0.200000
                        }
                      }
                    ]
                  }
                ]
                name "right_lower_leg"
                boundingObject Pose {
                  translation 0.000000 0.000000 0.100000
                  children [
                    Box {
                       size 0.100000 0.050000 0.200000
                    }
                  ]
                }
                physics Physics {
                  density -1
                  mass 0.500000
                  centerOfMass [ 0.000000 0.000000 0.100000 ]
                  inertiaMatrix [
                    1.000000e-02 1.000000e-02 1.000000e-02
                    0.000000e+00 0.000000e+00 0.000000e+00
                  ]
                }
              }
            }
          ]
          name "right_upper_leg"
          boundingObject Pose {
            translation 0.000000 0.000000 0.100000
            children [
              Box {
                 size 0.100000 0.050000 0.200000
              }
            ]
          }
          physics Physics {
            density -1
            mass 1.000000
            centerOfMass [ 0.000000 0.000000 0.100000 ]
            inertiaMatrix [
              1.000000e-02 1.000000e-02 1.000000e-02
              0.000000e+00 0.000000e+00 0.000000e+00
            ]
          }
        }
      }
    ]
    name IS name
    boundingObject Pose {
      translation 0.000000 0.000000 0.400000
      children [
        Box {
           size 0.300000 0.200000 0.100000
        }
      ]
    }
    physics Physics {
      density -1
      mass 5.000000
      centerOfMass [ 0.000000 0.000000 0.400000 ]
      inertiaMatrix [
        1.000000e-01 1.000000e-01 1.000000e-01
        0.000000e+00 0.000000e+00 0.000000e+00
      ]
    }
  }
}
