#VRML_SIM R2023b utf8

EXTERNPROTO "https://raw.githubusercontent.com/cyberbotics/webots/R2023b/projects/objects/backgrounds/protos/TexturedBackground.proto"
EXTERNPROTO "https://raw.githubusercontent.com/cyberbotics/webots/R2023b/projects/objects/backgrounds/protos/TexturedBackgroundLight.proto"
EXTERNPROTO "https://raw.githubusercontent.com/cyberbotics/webots/R2023b/projects/objects/floors/protos/RectangleArena.proto"
EXTERNPROTO "https://raw.githubusercontent.com/cyberbotics/webots/R2023b/projects/vehicles/protos/abstract/GenericTireAppearance.proto"
EXTERNPROTO "https://raw.githubusercontent.com/cyberbotics/webots/R2023b/projects/appearances/protos/CementTiles.proto"
EXTERNPROTO "https://raw.githubusercontent.com/cyberbotics/webots/R2023b/projects/appearances/protos/BrushedSteel.proto"

WorldInfo {
}
Viewpoint {
  orientation -0.18489398035747504 -0.14240040736159928 0.9723869291649391 4.4272100427438055
  position -3.6882347200307417 12.303044995237121 4.976975409984578
  follow "robot"
}
TexturedBackground {
  texture "factory"
}
TexturedBackgroundLight {
}
RectangleArena {
  translation -3.67 0 0
  floorSize 10 10
  floorTileSize 5 5
  wallThickness 0.1
  wallHeight 0.5
}
Robot {
  translation -7.85704 3.56215 0.197188
  rotation -0.9349945464926928 0.25099687825713124 -0.25057087846375703 1.63628
  children [
    Camera {
      translation 0.1 -0.13 0.01
      rotation 1 0 0 1.57081
      children [
        Shape {
          geometry Capsule {
            height 0.1
            radius 0.05
          }
        }
      ]
      fieldOfView 1
      width 640
      height 640
      far 2
    }
    DEF w4body HingeJoint {
      jointParameters HingeJointParameters {
        position 3803.3444366097333
        axis 0 0 1
        anchor -0.2 0.1 -0.1
      }
      device [
        DEF w4m RotationalMotor {
          name "w4m"
        }
      ]
      endPoint Solid {
        translation -0.20054295692586105 0.10106476557143827 -0.10031843426962617
        rotation 0 0 1 0.33676849105203244
        children [
          DEF w1body Shape {
            appearance GenericTireAppearance {
            }
            geometry Cylinder {
              height 0.05
              radius 0.1
            }
          }
        ]
        name "w4body"
        boundingObject USE w1body
        physics Physics {
        }
      }
    }
    DEF w3body HingeJoint {
      jointParameters HingeJointParameters {
        position -1272.9736473599569
        axis 0 0 1
        anchor -0.2 0.1 0.1
      }
      device [
        DEF w3m RotationalMotor {
          name "w3m"
        }
      ]
      endPoint Solid {
        translation -0.20085878346876762 0.10069905660150472 0.10034226342389552
        rotation 0 0 1 1.576595658655189
        children [
          DEF w1body Shape {
            appearance GenericTireAppearance {
            }
            geometry Cylinder {
              height 0.05
              radius 0.1
            }
          }
        ]
        name "w3body"
        boundingObject USE w1body
        physics Physics {
        }
      }
    }
    DEF w2body HingeJoint {
      jointParameters HingeJointParameters {
        position 4124.061475991018
        axis 0 0 1
        anchor 0.2 0.1 -0.1
      }
      device [
        DEF w2m RotationalMotor {
          name "w2m"
        }
      ]
      endPoint Solid {
        translation 0.20029520479799556 0.09988880026151746 -0.10059938630978404
        rotation 0 0 1 3.78435765585205
        children [
          DEF w1body Shape {
            appearance GenericTireAppearance {
            }
            geometry Cylinder {
              height 0.05
              radius 0.1
            }
          }
        ]
        name "w2body"
        boundingObject USE w1body
        physics Physics {
        }
      }
    }
    DEF w1body HingeJoint {
      jointParameters HingeJointParameters {
        position -417.7869453486954
        axis 0 0 1
        anchor 0.2 0.1 0.1
      }
      device [
        DEF w1m RotationalMotor {
          name "w1m"
        }
      ]
      endPoint Solid {
        translation 0.20037235250563867 0.09997441154503639 0.10004138756786851
        rotation 0 0 1 2.373626831873679
        children [
          DEF w1body Shape {
            appearance GenericTireAppearance {
            }
            geometry Cylinder {
              height 0.05
              radius 0.1
            }
          }
        ]
        name "w1body"
        boundingObject USE w1body
        physics Physics {
        }
      }
    }
    DEF body Shape {
      appearance PBRAppearance {
      }
      geometry Box {
        size 0.4 0.2 0.2
      }
    }
  ]
  boundingObject USE body
  physics Physics {
    mass 1
  }
  controller "my_controller1"
}
DEF balance Robot {
  translation -1.8344768682605954 0.8400000593538859 0.18796779232129804
  rotation 6.310143275589707e-08 -0.9999999999999977 2.4039511012992177e-08 1.5920925222942286
  children [
    HingeJoint {
      jointParameters HingeJointParameters {
        position -0.6490937528386136
        axis 0 1 0
        anchor 2 0 0
      }
      device [
        RotationalMotor {
        }
      ]
      endPoint DEF beam Solid {
        translation 1.8483399838075476 0 -0.9884327187464534
        rotation 1.9297983783356307e-07 -0.999999999999965 -1.8065517037762805e-07 0.6490937528386297
        children [
          Solid {
            translation 0 0 2.41
            children [
              DEF weight Shape {
                appearance BrushedSteel {
                }
                geometry Box {
                  size 0.3 0.3 0.3
                }
              }
            ]
            name "weight"
            boundingObject USE weight
            physics Physics {
            }
          }
          DEF beam Shape {
            geometry Cylinder {
              height 5
              radius 0.05
            }
          }
        ]
        name "beam"
        boundingObject USE beam
        physics Physics {
        }
      }
    }
    Solid {
      children [
        DEF base Shape {
          appearance CementTiles {
          }
          geometry Box {
            size 0.5 0.5 0.5
          }
        }
      ]
      name "base"
      boundingObject USE base
      physics Physics {
      }
    }
  ]
  name "balance"
  boundingObject USE base
  physics Physics {
  }
}
