#VRML_SIM R2023b utf8

EXTERNPROTO "https://raw.githubusercontent.com/cyberbotics/webots/R2023b/projects/objects/backgrounds/protos/TexturedBackground.proto"
EXTERNPROTO "https://raw.githubusercontent.com/cyberbotics/webots/R2023b/projects/objects/backgrounds/protos/TexturedBackgroundLight.proto"
EXTERNPROTO "https://raw.githubusercontent.com/cyberbotics/webots/R2023b/projects/objects/floors/protos/RectangleArena.proto"
EXTERNPROTO "https://raw.githubusercontent.com/cyberbotics/webots/R2023b/projects/vehicles/protos/abstract/GenericTireAppearance.proto"
EXTERNPROTO "https://raw.githubusercontent.com/cyberbotics/webots/R2023b/projects/appearances/protos/CementTiles.proto"

WorldInfo {
}
Viewpoint {
  orientation -0.18489398035747504 -0.14240040736159928 0.9723869291649391 4.4272100427438055
  position 1.9932611985200872 10.279380911041466 5.452485174542108
  follow "robot"
}
TexturedBackground {
  texture "factory"
}
TexturedBackgroundLight {
}
RectangleArena {
  translation -3.67 0 0
  floorSize 10 10
  floorTileSize 5 5
  wallThickness 0.1
  wallHeight 0.5
}
Robot {
  translation -6.682957269083748 2.881516565484771 0.19864668559539592
  rotation -0.9353106174737401 0.24991205697632368 -0.2504755728983443 1.638730339241704
  children [
    Camera {
      translation 0.1 -0.13 0.01
      rotation 1 0 0 1.57081
      children [
        Shape {
          geometry Capsule {
            height 0.1
            radius 0.05
          }
        }
      ]
      fieldOfView 1
      width 640
      height 640
      far 2
    }
    DEF w4body HingeJoint {
      jointParameters HingeJointParameters {
        position 3816.915534808006
        axis 0 0 1
        anchor -0.2 0.1 -0.1
      }
      device [
        DEF w4m RotationalMotor {
          name "w4m"
        }
      ]
      endPoint Solid {
        translation -0.20118987672658403 0.10011278883364233 -0.10031843426962617
        rotation 0 0 1 1.34149607496578
        children [
          DEF w1body Shape {
            appearance GenericTireAppearance {
            }
            geometry Cylinder {
              height 0.05
              radius 0.1
            }
          }
        ]
        name "w4body"
        boundingObject USE w1body
        physics Physics {
        }
      }
    }
    DEF w3body HingeJoint {
      jointParameters HingeJointParameters {
        position -1259.4025371619218
        axis 0 0 1
        anchor -0.2 0.1 0.1
      }
      device [
        DEF w3m RotationalMotor {
          name "w3m"
        }
      ]
      endPoint Solid {
        translation -0.2010505918533867 0.09965007724290442 0.10034226342389552
        rotation 0 0 1 2.5813352423310736
        children [
          DEF w1body Shape {
            appearance GenericTireAppearance {
            }
            geometry Cylinder {
              height 0.05
              radius 0.1
            }
          }
        ]
        name "w3body"
        boundingObject USE w1body
        physics Physics {
        }
      }
    }
    DEF w2body HingeJoint {
      jointParameters HingeJointParameters {
        position 4137.632583666774
        axis 0 0 1
        anchor 0.2 0.1 -0.1
      }
      device [
        DEF w2m RotationalMotor {
          name "w2m"
        }
      ]
      endPoint Solid {
        translation 0.20025217624430036 0.10018952149326328 -0.10059938630978404
        rotation 0 0 1 4.789094717249015
        children [
          DEF w2body Shape {
            appearance GenericTireAppearance {
            }
            geometry Cylinder {
              height 0.05
              radius 0.1
            }
          }
        ]
        name "w2body"
        boundingObject USE w2body
        physics Physics {
        }
      }
    }
    DEF w1body HingeJoint {
      jointParameters HingeJointParameters {
        position -404.21583774848153
        axis 0 0 1
        anchor 0.2 0.1 0.1
      }
      device [
        DEF w1m RotationalMotor {
          name "w1m"
        }
      ]
      endPoint Solid {
        translation 0.2002212936470024 0.1003005499613695 0.10004138756786851
        rotation 0 0 0.9999999999999999 3.378363817728356
        children [
          DEF w1body Shape {
            appearance GenericTireAppearance {
            }
            geometry Cylinder {
              height 0.05
              radius 0.1
            }
          }
        ]
        name "w1body"
        boundingObject USE w1body
        physics Physics {
        }
      }
    }
    DEF body Shape {
      appearance PBRAppearance {
      }
      geometry Box {
        size 0.4 0.2 0.2
      }
    }
  ]
  boundingObject USE body
  physics Physics {
    mass 1
  }
  controller "my_controller1"
  linearVelocity 0.4308697270868452 -0.2485985955645576 -0.00223880978285939
  angularVelocity -0.008266187069090344 -0.01608694615305104 0.00011096855195692995
}
DEF balance Robot {
  translation -1.8217901887449943 0.8400000697440551 0.19368213637469445
  rotation 4.7243600577019504e-08 -0.9999999999999978 4.6365974167127136e-08 1.5460466098758427
  children [
    HingeJoint {
      jointParameters HingeJointParameters {
        position 0.47124998330049783
        axis 0 1 0
        anchor 2 0 0
      }
      device [
        RotationalMotor {
        }
      ]
      endPoint DEF beam Solid {
        translation 1.0441346180769566 0 -0.29380498913584724
        rotation 9.219769489231549e-08 0.9999999999999347 -3.491076954174706e-07 0.47124998330053175
        children [
          DEF beam Shape {
            geometry Cylinder {
              height 5
              radius 0.05
            }
          }
        ]
        name "beam"
        boundingObject USE beam
        physics Physics {
        }
      }
    }
    Solid {
      children [
        DEF base Shape {
          appearance CementTiles {
          }
          geometry Box {
            size 0.5 0.5 0.5
          }
        }
      ]
      name "base"
      boundingObject USE base
      physics Physics {
      }
    }
  ]
  name "balance"
  boundingObject USE base
  physics Physics {
  }
  linearVelocity 1.556117355548523e-06 -9.814157068225863e-10 -5.192800501764456e-06
  angularVelocity 4.041396081447607e-09 -6.51277879137212e-05 4.75033898851516e-10
}
